Workbook

Sheet Sheet1
A3: Count of id | B3: Column Labels
A4: Row Labels | B4: banner_partner | C4: facebook_lal | D4: facebook_retargeting | E4: facebook_tier1 | F4: facebOOK_tier2 | G4: google_hot | H4: google_wide | I4: instagram_blogger | J4: instagram_tier1 | K4: instagram_tier2 | L4: youtube_blogger | M4: Grand Total
A5: 2021-02-01 | B5: 1 | C5: 1 | D5: 1 | E5: 1 | F5: 1 | G5: 1 | H5: 1 | I5: 1 | J5: 1 | K5: 1 | L5: 1 | M5: 11
A6: 2021-02-02 | B6: 1 | C6: 1 | D6: 1 | E6: 1 | F6: 1 | G6: 1 | H6: 1 | I6: 1 | J6: 1 | K6: 1 | L6: 1 | M6: 11
A7: 2021-02-03 | B7: 1 | C7: 1 | D7: 1 | E7: 1 | F7: 1 | G7: 1 | H7: 1 | I7: 1 | J7: 1 | K7: 1 | L7: 1 | M7: 11
A8: 2021-02-04 | B8: 1 | C8: 1 | D8: 1 | E8: 1 | F8: 1 | G8: 1 | H8: 1 | I8: 1 | J8: 1 | K8: 1 | L8: 1 | M8: 11
A9: 2021-02-05 | B9: 1 | C9: 1 | D9: 1 | E9: 1 | F9: 1 | G9: 1 | H9: 1 | I9: 1 | J9: 1 | K9: 1 | L9: 1 | M9: 11
A10: 2021-02-06 | B10: 1 | C10: 1 | D10: 1 | E10: 1 | F10: 1 | G10: 1 | H10: 1 | I10: 1 | J10: 1 | K10: 1 | L10: 1 | M10: 11
A11: 2021-02-07 | B11: 1 | C11: 1 | D11: 1 | E11: 1 | F11: 1 | G11: 1 | H11: 1 | I11: 1 | J11: 1 | K11: 1 | L11: 1 | M11: 11
A12: 2021-02-08 | B12: 1 | C12: 1 | D12: 1 | E12: 1 | F12: 1 | G12: 1 | H12: 1 | I12: 1 | J12: 1 | K12: 1 | L12: 1 | M12: 11
A13: 2021-02-09 | B13: 1 | C13: 1 | D13: 1 | E13: 1 | F13: 1 | G13: 1 | H13: 1 | I13: 1 | J13: 1 | K13: 1 | L13: 1 | M13: 11
A14: 2021-02-10 | B14: 1 | C14: 1 | D14: 1 | E14: 1 | F14: 1 | G14: 1 | H14: 1 | I14: 1 | J14: 1 | K14: 1 | L14: 1 | M14: 11
A15: 2021-02-11 | B15: 1 | C15: 1 | D15: 1 | E15: 1 | F15: 1 | G15: 1 | H15: 1 | I15: 1 | J15: 1 | K15: 1 | L15: 1 | M15: 11
A16: 2021-02-12 | B16: 1 | C16: 1 | D16: 1 | E16: 1 | F16: 1 | G16: 1 | H16: 1 | I16: 1 | J16: 1 | K16: 1 | L16: 1 | M16: 11
... A33: Grand Total | B33: 28 | C33: 28 | D33: 28 | E33: 28 | F33: 28 | G33: 28 | H33: 28 | I33: 28 | J33: 28 | K33: 28 | L33: 28 | M33: 308

Sheet Sheet2
A3: Row Labels
A4: 10934
A5: youtube_blogger
A6: 39889
A7: banner_partner
A8: 127823
A9: google_wide
A10: 348934
A11: facebook_tier2
A12: 349043
A13: facebook_tier1
A14: 374754
A15: instagram_blogger
A16: 544756
A17: facebook_lal
A18: 983498
A19: instagram_tier2
A20: 4387490
A21: facebook_retargeting
A22: 9034945
A23: instagram_tier1
A24: 89459845
A25: google_hot
A26: Grand Total

Sheet Sheet3
A3: Row Labels
A4: banner_partner
A5: media
A6: facebook_lal
A7: social
A8: facebook_retargeting
A9: social
A10: facebook_tier1
A11: social
A12: facebOOK_tier2
A13: social
A14: google_hot
... A26: Grand Total

Sheet Cleaned_data
A1: Marketing
A2: id | B2: c_date | C2: date_clean | D2: campaign_name | E2: campaign_name_clean | F2: category | G2: campaign_id | H2: impressions | I2: mark_spent | J2: CTR | K2: clicks | L2: clicks_gt_impressions | M2: leads | N2: leads_gt_clicks | O2: orders | P2: orders_gt_leads | Q2: revenue | R2: impressions_remainder | S2: clicks_remainder | T2: leads_remainder | U2: orders_remainder
A3: 242 | B3: 2021-02-22 | C3: =DATEVALUE(B3) -> 44249 | D3: banner_partner | E3: =TRIM(LOWER(D3)) -> banner_partner | F3: media | G3: 39889 | H3: 105873774 | I3: 60021.6 | J3: =(K3)/(H3) -> 7.9424769e-05 | K3: 8409 | L3: =(K3)>(H3) -> FALSE | M3: 168 | N3: =M3>K3 -> FALSE | O3: 20 | P3: =(O3)>(M3) -> FALSE | Q3: 80600 | R3: =MOD(H3, 1) -> 0 | S3: =MOD(K3, 1) -> 0 | T3: =MOD(M3,1) -> 0 | U3: =MOD(O3,1) -> 0
A4: 11 | B4: 2021-02-01 | C4: =DATEVALUE(B4) -> 44228 | D4: banner_partner | E4: =TRIM(LOWER(D4)) -> banner_partner | F4: media | G4: 39889 | H4: 20900000 | I4: 931.99 | J4: =(K4)/(H4) -> 0.0001 | K4: 2090 | L4: =(K4)>(H4) -> FALSE | M4: 3 | N4: =(M4)>(K4) -> FALSE | O4: 0 | P4: =(O3)>(M3) -> FALSE | Q4: 0 | R4: =MOD(H4, 1) -> 0 | S4: =MOD(K4, 1) -> 0 | T4: =MOD(M4,1) -> 0 | U4: =MOD(O4,1) -> 0
A5: 22 | B5: 2021-02-02 | C5: =DATEVALUE(B5) -> 44229 | D5: banner_partner | E5: =TRIM(LOWER(D5)) -> banner_partner | F5: media | G5: 39889 | H5: 42000000 | I5: 46159.8 | J5: =(K5)/(H5) -> 0.0001 | K5: 4200 | L5: =(K5)>(H5) -> FALSE | M5: 92 | N5: =(M5)>(K5) -> FALSE | O5: 13 | P5: =(O4)>(M4) -> FALSE | Q5: 51753 | R5: =MOD(H5, 1) -> 0 | S5: =MOD(K5, 1) -> 0 | T5: =MOD(M5,1) -> 0 | U5: =MOD(O5,1) -> 0
A6: 33 | B6: 2021-02-03 | C6: =DATEVALUE(B6) -> 44230 | D6: banner_partner | E6: =TRIM(LOWER(D6)) -> banner_partner | F6: media | G6: 39889 | H6: 125910000 | I6: 29378.3 | J6: =(K6)/(H6) -> 0.0001 | K6: 12591 | L6: =(K6)>(H6) -> FALSE | M6: 68 | N6: =(M6)>(K6) -> FALSE | O6: 13 | P6: =(O5)>(M5) -> FALSE | Q6: 51753 | R6: =MOD(H6, 1) -> 0 | S6: =MOD(K6, 1) -> 0 | T6: =MOD(M6,1) -> 0 | U6: =MOD(O6,1) -> 0
A7: 66 | B7: 2021-02-06 | C7: =DATEVALUE(B7) -> 44233 | D7: banner_partner | E7: =TRIM(LOWER(D7)) -> banner_partner | F7: media | G7: 39889 | H7: 42070000 | I7: 38185.2 | J7: =(K7)/(H7) -> 0.0001 | K7: 4207 | L7: =(K7)>(H7) -> FALSE | M7: 84 | N7: =(M7)>(K7) -> FALSE | O7: 10 | P7: =(O6)>(M6) -> FALSE | Q7: 48820 | R7: =MOD(H7, 1) -> 0 | S7: =MOD(K7, 1) -> 0 | T7: =MOD(M7,1) -> 0 | U7: =MOD(O7,1) -> 0
A8: 198 | B8: 2021-02-18 | C8: =DATEVALUE(B8) -> 44245 | D8: banner_partner | E8: =TRIM(LOWER(D8)) -> banner_partner | F8: media | G8: 39889 | H8: 419970000 | I8: 339735 | J8: =(K8)/(H8) -> 0.0001 | K8: 41997 | L8: =(K8)>(H8) -> FALSE | M8: 840 | N8: =(M8)>(K8) -> FALSE | O8: 114 | P8: =(O7)>(M7) -> FALSE | Q8: 516420 | R8: =MOD(H8, 1) -> 0 | S8: =MOD(K8, 1) -> 0 | T8: =MOD(M8,1) -> 0 | U8: =MOD(O8,1) -> 0
A9: 231 | B9: 2021-02-21 | C9: =DATEVALUE(B9) -> 44248 | D9: banner_partner | E9: =TRIM(LOWER(D9)) -> banner_partner | F9: media | G9: 39889 | H9: 42080000 | I9: 25023.2 | J9: =(K9)/(H9) -> 0.0001 | K9: 4208 | L9: =(K9)>(H9) -> FALSE | M9: 67 | N9: =(M9)>(K9) -> FALSE | O9: 10 | P9: =(O8)>(M8) -> FALSE | Q9: 31710 | R9: =MOD(H9, 1) -> 0 | S9: =MOD(K9, 1) -> 0 | T9: =MOD(M9,1) -> 0 | U9: =MOD(O9,1) -> 0
A10: 286 | B10: 2021-02-26 | C10: =DATEVALUE(B10) -> 44253 | D10: banner_partner | E10: =TRIM(LOWER(D10)) -> banner_partner | F10: media | G10: 39889 | H10: 20930000 | I10: 8087.73 | J10: =(K10)/(H10) -> 0.0001 | K10: 2093 | L10: =(K10)>(H10) -> FALSE | M10: 22 | N10: =(M10)>(K10) -> FALSE | O10: 3 | P10: =(O9)>(M9) -> FALSE | Q10: 12213 | R10: =MOD(H10, 1) -> 0 | S10: =MOD(K10, 1) -> 0 | T10: =MOD(M10,1) -> 0 | U10: =MOD(O10,1) -> 0
A11: 308 | B11: 2021-02-28 | C11: =DATEVALUE(B11) -> 44255 | D11: banner_partner | E11: =TRIM(LOWER(D11)) -> banner_partner | F11: media | G11: 39889 | H11: 8490000 | I11: 6822.62 | J11: =(K11)/(H11) -> 0.0001 | K11: 849 | L11: =(K11)>(H11) -> FALSE | M11: 18 | N11: =(M11)>(K11) -> FALSE | O11: 2 | P11: =(O10)>(M10) -> FALSE | Q11: 7030 | R11: =MOD(H11, 1) -> 0 | S11: =MOD(K11, 1) -> 0 | T11: =MOD(M11,1) -> 0 | U11: =MOD(O11,1) -> 0
A12: 275 | B12: 2021-02-25 | C12: =DATEVALUE(B12) -> 44252 | D12: banner_partner | E12: =TRIM(LOWER(D12)) -> banner_partner | F12: media | G12: 39889 | H12: 2885291 | I12: 7583.66 | J12: =(K12)/(H12) -> 0.0002939045 | K12: 848 | L12: =(K12)>(H12) -> FALSE | M12: 17 | N12: =(M12)>(K12) -> FALSE | O12: 3 | P12: =(O11)>(M11) -> FALSE | Q12: 11943 | R12: =MOD(H12, 1) -> 0 | S12: =MOD(K12, 1) -> 0 | T12: =MOD(M12,1) -> 0 | U12: =MOD(O12,1) -> 0
A13: 44 | B13: 2021-02-04 | C13: =DATEVALUE(B13) -> 44231 | D13: banner_partner | E13: =TRIM(LOWER(D13)) -> banner_partner | F13: media | G13: 39889 | H13: 41924802 | I13: 177746 | J13: =(K13)/(H13) -> 0.00040086057 | K13: 16806 | L13: =(K13)>(H13) -> FALSE | M13: 336 | N13: =(M13)>(K13) -> FALSE | O13: 60 | P13: =(O12)>(M12) -> FALSE | Q13: 204540 | R13: =MOD(H13, 1) -> 0 | S13: =MOD(K13, 1) -> 0 | T13: =MOD(M13,1) -> 0 | U13: =MOD(O13,1) -> 0
A14: 176 | B14: 2021-02-16 | C14: =DATEVALUE(B14) -> 44243 | D14: banner_partner | E14: =TRIM(LOWER(D14)) -> banner_partner | F14: media | G14: 39889 | H14: 56876855 | I14: 206424 | J14: =(K14)/(H14) -> 0.00059060931 | K14: 33592 | L14: =(K14)>(H14) -> FALSE | M14: 416 | N14: =(M14)>(K14) -> FALSE | O14: 62 | P14: =(O13)>(M13) -> FALSE | Q14: 246822 | R14: =MOD(H14, 1) -> 0 | S14: =MOD(K14, 1) -> 0 | T14: =MOD(M14,1) -> 0 | U14: =MOD(O14,1) -> 0
A15: 77 | B15: 2021-02-07 | C15: =DATEVALUE(B15) -> 44234 | D15: banner_partner | E15: =TRIM(LOWER(D15)) -> banner_partner | F15: media | G15: 39889 | H15: 3957603 | I15: 79987.7 | J15: =(K15)/(H15) -> 0.0010620065 | K15: 4203 | L15: =(K15)>(H15) -> FALSE | M15: 142 | N15: =(M15)>(K15) -> FALSE | O15: 27 | P15: =(O14)>(M14) -> FALSE | Q15: 90504 | R15: =MOD(H15, 1) -> 0 | S15: =MOD(K15, 1) -> 0 | T15: =MOD(M15,1) -> 0 | U15: =MOD(O15,1) -> 0
... A180: 39 | B180: 2021-02-04 | C180: =DATEVALUE(B180) -> 44231 | D180: instagram_tier1 | E180: =TRIM(LOWER(D180)) -> instagram_tier1 | F180: social | G180: 9034945 | H180: 1322751 | I180: 104028 | J180: =(K180)/(H180) -> 0.008160266 | K180: 10794 | L180: =(K180)>(H180) -> FALSE | M180: 238 | N180: =(M180)>(K180) -> FALSE | O180: 27 | P180: =(O179)>(M179) -> FALSE | Q180: 179037 | R180: =MOD(H180, 1) -> 0 | S180: =MOD(K180, 1) -> 0 | T180: =MOD(M180,1) -> 0 | U180: =MOD(O180,1) -> 0
A181: 1 | B181: 2021-02-01 | C181: =DATEVALUE(B181) -> 44228 | D181: facebook_tier1 | E181: =TRIM(LOWER(D181)) -> facebook_tier1 | F181: social | G181: 349043 | H181: 148263 | I181: 7307.37 | J181: =(K181)/(H181) -> 0.0081611731 | K181: 1210 | L181: =(K181)>(H181) -> FALSE | M181: 13 | N181: =(M181)>(K181) -> FALSE | O181: 1 | P181: =(O181)>(M181) -> FALSE | Q181: 4981 | R181: =MOD(H181, 1) -> 0 | S181: =MOD(K181, 1) -> 0 | T181: =MOD(M181,1) -> 0 | U181: =MOD(O181,1) -> 0
A182: 260 | B182: 2021-02-24 | C182: =DATEVALUE(B182) -> 44251 | D182: instagram_tier2 | E182: =TRIM(LOWER(D182)) -> instagram_tier2 | F182: social | G182: 983498 | H182: 624157 | I182: 18675 | J182: =(K182)/(H182) -> 0.0081678168 | K182: 5098 | L182: =(K182)>(H182) -> FALSE | M182: 122 | N182: =(M182)>(K182) -> FALSE | O182: 6 | P182: =(O181)>(M181) -> FALSE | Q182: 10590 | R182: =MOD(H182, 1) -> 0 | S182: =MOD(K182, 1) -> 0 | T182: =MOD(M182,1) -> 0 | U182: =MOD(O182,1) -> 0
A183: 170 | B183: 2021-02-16 | C183: =DATEVALUE(B183) -> 44243 | D183: youtube_blogger | E183: =TRIM(LOWER(D183)) -> youtube_blogger | F183: influencer | G183: 10934 | H183: 4371118 | I183: 221258 | J183: =(K183)/(H183) -> 0.0082356505 | K183: 35999 | L183: =(K183)>(H183) -> FALSE | M183: 720 | N183: =(M183)>(K183) -> FALSE | O183: 128 | P183: =(O182)>(M182) -> FALSE | Q183: 1021570 | R183: =MOD(H183, 1) -> 0 | S183: =MOD(K183, 1) -> 0 | T183: =MOD(M183,1) -> 0 | U183: =MOD(O183,1) -> 0
A184: 257 | B184: 2021-02-24 | C184: =DATEVALUE(B184) -> 44251 | D184: google_wide | E184: =TRIM(LOWER(D184)) -> google_wide | F184: search | G184: 127823 | H184: 291441 | I184: 22357.6 | J184: =(K184)/(H184) -> 0.0082623927 | K184: 2408 | L184: =(K184)>(H184) -> FALSE | M184: 52 | N184: =(M184)>(K184) -> FALSE | O184: 5 | P184: =(O183)>(M183) -> FALSE | Q184: 19060 | R184: =MOD(H184, 1) -> 0 | S184: =MOD(K184, 1) -> 0 | T184: =MOD(M184,1) -> 0 | U184: =MOD(O184,1) -> 0
A185: 87 | B185: 2021-02-08 | C185: =DATEVALUE(B185) -> 44235 | D185: instagram_blogger | E185: =TRIM(LOWER(D185)) -> instagram_blogger | F185: influencer | G185: 374754 | H185: 361650 | I185: 31154.3 | J185: =(K185)/(H185) -> 0.0082704272 | K185: 2991 | L185: =(K185)>(H185) -> FALSE | M185: 60 | N185: =(M185)>(K185) -> FALSE | O185: 9 | P185: =(O184)>(M184) -> FALSE | Q185: 45027 | R185: =MOD(H185, 1) -> 0 | S185: =MOD(K185, 1) -> 0 | T185: =MOD(M185,1) -> 0 | U185: =MOD(O185,1) -> 0
A186: 255 | B186: 2021-02-24 | C186: =DATEVALUE(B186) -> 44251 | D186: facebOOK_tier2 | E186: =TRIM(LOWER(D186)) -> facebook_tier2 | F186: social | G186: 348934 | H186: 395127 | I186: 44347.2 | J186: =(K186)/(H186) -> 0.0083441526 | K186: 3297 | L186: =(K186)>(H186) -> FALSE | M186: 66 | N186: =(M186)>(K186) -> FALSE | O186: 7 | P186: =(O185)>(M185) -> FALSE | Q186: 34867 | R186: =MOD(H186, 1) -> 0 | S186: =MOD(K186, 1) -> 0 | T186: =MOD(M186,1) -> 0 | U186: =MOD(O186,1) -> 0
A187: 295 | B187: 2021-02-27 | C187: =DATEVALUE(B187) -> 44254 | D187: facebook_lal | E187: =TRIM(LOWER(D187)) -> facebook_lal | F187: social | G187: 544756 | H187: 13693 | I187: 3098.45 | J187: =(K187)/(H187) -> 0.0083984518 | K187: 115 | L187: =(K187)>(H187) -> FALSE | M187: 2 | N187: =(M187)>(K187) -> FALSE | O187: 0 | P187: =(O186)>(M186) -> FALSE | Q187: 0 | R187: =MOD(H187, 1) -> 0 | S187: =MOD(K187, 1) -> 0 | T187: =MOD(M187,1) -> 0 | U187: =MOD(O187,1) -> 0
A188: 263 | B188: 2021-02-24 | C188: =DATEVALUE(B188) -> 44251 | D188: instagram_blogger | E188: =TRIM(LOWER(D188)) -> instagram_blogger | F188: influencer | G188: 374754 | H188: 355802 | I188: 42311.5 | J188: =(K188)/(H188) -> 0.0084035503 | K188: 2990 | L188: =(K188)>(H188) -> FALSE | M188: 60 | N188: =(M188)>(K188) -> FALSE | O188: 9 | P188: =(O187)>(M187) -> FALSE | Q188: 44829 | R188: =MOD(H188, 1) -> 0 | S188: =MOD(K188, 1) -> 0 | T188: =MOD(M188,1) -> 0 | U188: =MOD(O188,1) -> 0
A189: 38 | B189: 2021-02-04 | C189: =DATEVALUE(B189) -> 44231 | D189: youtube_blogger | E189: =TRIM(LOWER(D189)) -> youtube_blogger | F189: influencer | G189: 10934 | H189: 2120555 | I189: 185263 | J189: =(K189)/(H189) -> 0.0084850428 | K189: 17993 | L189: =(K189)>(H189) -> FALSE | M189: 445 | N189: =(M189)>(K189) -> FALSE | O189: 89 | P189: =(O188)>(M188) -> FALSE | Q189: 624958 | R189: =MOD(H189, 1) -> 0 | S189: =MOD(K189, 1) -> 0 | T189: =MOD(M189,1) -> 0 | U189: =MOD(O189,1) -> 0
A190: 303 | B190: 2021-02-28 | C190: =DATEVALUE(B190) -> 44255 | D190: instagram_tier1 | E190: =TRIM(LOWER(D190)) -> instagram_tier1 | F190: social | G190: 9034945 | H190: 63566 | I190: 4950.74 | J190: =(K190)/(H190) -> 0.0085894975 | K190: 546 | L190: =(K190)>(H190) -> FALSE | M190: 12 | N190: =(M190)>(K190) -> FALSE | O190: 1 | P190: =(O189)>(M189) -> FALSE | Q190: 5981 | R190: =MOD(H190, 1) -> 0 | S190: =MOD(K190, 1) -> 0 | T190: =MOD(M190,1) -> 0 | U190: =MOD(O190,1) -> 0
A191: 98 | B191: 2021-02-09 | C191: =DATEVALUE(B191) -> 44236 | D191: instagram_blogger | E191: =TRIM(LOWER(D191)) -> instagram_blogger | F191: influencer | G191: 374754 | H191: 346068 | I191: 57642.4 | J191: =(K191)/(H191) -> 0.0086861542 | K191: 3006 | L191: =(K191)>(H191) -> FALSE | M191: 99 | N191: =(M191)>(K191) -> FALSE | O191: 15 | P191: =(O190)>(M190) -> FALSE | Q191: 89460 | R191: =MOD(H191, 1) -> 0 | S191: =MOD(K191, 1) -> 0 | T191: =MOD(M191,1) -> 0 | U191: =MOD(O191,1) -> 0
A192: 301 | B192: 2021-02-28 | C192: =DATEVALUE(B192) -> 44255 | D192: google_wide | E192: =TRIM(LOWER(D192)) -> google_wide | F192: search | G192: 127823 | H192: 55625 | I192: 384.75 | J192: =(K192)/(H192) -> 0.0087550562 | K192: 487 | L192: =(K192)>(H192) -> FALSE | M192: 1 | N192: =(M192)>(K192) -> FALSE | O192: 0 | P192: =(O191)>(M191) -> FALSE | Q192: 0 | R192: =MOD(H192, 1) -> 0 | S192: =MOD(K192, 1) -> 0 | T192: =MOD(M192,1) -> 0 | U192: =MOD(O192,1) -> 0
A193: 271 | B193: 2021-02-25 | C193: =DATEVALUE(B193) -> 44252 | D193: instagram_tier2 | E193: =TRIM(LOWER(D193)) -> instagram_tier2 | F193: social | G193: 983498 | H193: 115468 | I193: 2059.03 | J193: =(K193)/(H193) -> 0.0087903142 | K193: 1015 | L193: =(K193)>(H193) -> FALSE | M193: 20 | N193: =(M193)>(K193) -> FALSE | O193: 1 | P193: =(O192)>(M192) -> FALSE | Q193: 1981 | R193: =MOD(H193, 1) -> 0 | S193: =MOD(K193, 1) -> 0 | T193: =MOD(M193,1) -> 0 | U193: =MOD(O193,1) -> 0
... A250: 218 | B250: 2021-02-20 | C250: =DATEVALUE(B250) -> 44247 | D250: facebook_lal | E250: =TRIM(LOWER(D250)) -> facebook_lal | F250: social | G250: 544756 | H250: 1118531 | I250: 173041 | J250: =(K250)/(H250) -> 0.012873134 | K250: 14399 | L250: =(K250)>(H250) -> FALSE | M250: 113 | N250: =(M250)>(K250) -> FALSE | O250: 18 | P250: =(O249)>(M249) -> FALSE | Q250: 17658 | R250: =MOD(H250, 1) -> 0 | S250: =MOD(K250, 1) -> 0 | T250: =MOD(M250,1) -> 0 | U250: =MOD(O250,1) -> 0
A251: 203 | B251: 2021-02-19 | C251: =DATEVALUE(B251) -> 44246 | D251: youtube_blogger | E251: =TRIM(LOWER(D251)) -> youtube_blogger | F251: influencer | G251: 10934 | H251: 3801165 | I251: 880357 | J251: =(K251)/(H251) -> 0.013024954 | K251: 49510 | L251: =(K251)>(H251) -> FALSE | M251: 1666 | N251: =(M251)>(K251) -> FALSE | O251: 369 | P251: =(O251)>(M251) -> FALSE | Q251: 2812520 | R251: =MOD(H251, 1) -> 0 | S251: =MOD(K251, 1) -> 0 | T251: =MOD(M251,1) -> 0 | U251: =MOD(O251,1) -> 0
A252: 27 | B252: 2021-02-03 | C252: =DATEVALUE(B252) -> 44230 | D252: youtube_blogger | E252: =TRIM(LOWER(D252)) -> youtube_blogger | F252: influencer | G252: 10934 | H252: 1035261 | I252: 189341 | J252: =(K252)/(H252) -> 0.013043088 | K252: 13503 | L252: =(K252)>(H252) -> FALSE | M252: 455 | N252: =(M252)>(K252) -> FALSE | O252: 91 | P252: =(O251)>(M251) -> FALSE | Q252: 772499 | R252: =MOD(H252, 1) -> 0 | S252: =MOD(K252, 1) -> 0 | T252: =MOD(M252,1) -> 0 | U252: =MOD(O252,1) -> 0
A253: 32 | B253: 2021-02-03 | C253: =DATEVALUE(B253) -> 44230 | D253: instagram_blogger | E253: =TRIM(LOWER(D253)) -> instagram_blogger | F253: influencer | G253: 374754 | H253: 667352 | I253: 194336 | J253: =(K253)/(H253) -> 0.013480142 | K253: 8996 | L253: =(K253)>(H253) -> FALSE | M253: 342 | N253: =(M253)>(K253) -> FALSE | O253: 51 | P253: =(O252)>(M252) -> FALSE | Q253: 254031 | R253: =MOD(H253, 1) -> 0 | S253: =MOD(K253, 1) -> 0 | T253: =MOD(M253,1) -> 0 | U253: =MOD(O253,1) -> 0
A254: 126 | B254: 2021-02-12 | C254: =DATEVALUE(B254) -> 44239 | D254: youtube_blogger | E254: =TRIM(LOWER(D254)) -> youtube_blogger | F254: influencer | G254: 10934 | H254: 1299708 | I254: 121652 | J254: =(K254)/(H254) -> 0.013844648 | K254: 17994 | L254: =(K254)>(H254) -> FALSE | M254: 378 | N254: =(M254)>(K254) -> FALSE | O254: 61 | P254: =(O253)>(M253) -> FALSE | Q254: 486841 | R254: =MOD(H254, 1) -> 0 | S254: =MOD(K254, 1) -> 0 | T254: =MOD(M254,1) -> 0 | U254: =MOD(O254,1) -> 0
A255: 300 | B255: 2021-02-28 | C255: =DATEVALUE(B255) -> 44255 | D255: google_hot | E255: =TRIM(LOWER(D255)) -> google_hot | F255: search | G255: 89459845 | H255: 11554 | I255: 3529.73 | J255: =(K255)/(H255) -> 0.016184871 | K255: 187 | L255: =(K255)>(H255) -> FALSE | M255: 5 | N255: =(M255)>(K255) -> FALSE | O255: 1 | P255: =(O254)>(M254) -> FALSE | Q255: 8714 | R255: =MOD(H255, 1) -> 0 | S255: =MOD(K255, 1) -> 0 | T255: =MOD(M255,1) -> 0 | U255: =MOD(O255,1) -> 0
A256: 102 | B256: 2021-02-10 | C256: =DATEVALUE(B256) -> 44237 | D256: google_hot | E256: =TRIM(LOWER(D256)) -> google_hot | F256: search | G256: 89459845 | H256: 108748 | I256: 51883.1 | J256: =(K256)/(H256) -> 0.016524442 | K256: 1797 | L256: =(K256)>(H256) -> FALSE | M256: 57 | N256: =(M256)>(K256) -> FALSE | O256: 11 | P256: =(O255)>(M255) -> FALSE | Q256: 86724 | R256: =MOD(H256, 1) -> 0 | S256: =MOD(K256, 1) -> 0 | T256: =MOD(M256,1) -> 0 | U256: =MOD(O256,1) -> 0
A257: 179 | B257: 2021-02-17 | C257: =DATEVALUE(B257) -> 44244 | D257: google_hot | E257: =TRIM(LOWER(D257)) -> google_hot | F257: search | G257: 89459845 | H257: 490058 | I257: 116213 | J257: =(K257)/(H257) -> 0.016536818 | K257: 8104 | L257: =(K257)>(H257) -> FALSE | M257: 162 | N257: =(M257)>(K257) -> FALSE | O257: 31 | P257: =(O256)>(M256) -> FALSE | Q257: 227726 | R257: =MOD(H257, 1) -> 0 | S257: =MOD(K257, 1) -> 0 | T257: =MOD(M257,1) -> 0 | U257: =MOD(O257,1) -> 0
A258: 190 | B258: 2021-02-18 | C258: =DATEVALUE(B258) -> 44245 | D258: google_hot | E258: =TRIM(LOWER(D258)) -> google_hot | F258: search | G258: 89459845 | H258: 527210 | I258: 119542 | J258: =(K258)/(H258) -> 0.017078583 | K258: 9004 | L258: =(K258)>(H258) -> FALSE | M258: 162 | N258: =(M258)>(K258) -> FALSE | O258: 28 | P258: =(O257)>(M257) -> FALSE | Q258: 214368 | R258: =MOD(H258, 1) -> 0 | S258: =MOD(K258, 1) -> 0 | T258: =MOD(M258,1) -> 0 | U258: =MOD(O258,1) -> 0
A259: 80 | B259: 2021-02-08 | C259: =DATEVALUE(B259) -> 44235 | D259: google_hot | E259: =TRIM(LOWER(D259)) -> google_hot | F259: search | G259: 89459845 | H259: 51350 | I259: 6918.85 | J259: =(K259)/(H259) -> 0.017604674 | K259: 904 | L259: =(K259)>(H259) -> FALSE | M259: 20 | N259: =(M259)>(K259) -> FALSE | O259: 2 | P259: =(O258)>(M258) -> FALSE | Q259: 16240 | R259: =MOD(H259, 1) -> 0 | S259: =MOD(K259, 1) -> 0 | T259: =MOD(M259,1) -> 0 | U259: =MOD(O259,1) -> 0
A260: 289 | B260: 2021-02-27 | C260: =DATEVALUE(B260) -> 44254 | D260: google_hot | E260: =TRIM(LOWER(D260)) -> google_hot | F260: search | G260: 89459845 | H260: 4662 | I260: 1754.25 | J260: =(K260)/(H260) -> 0.017803518 | K260: 83 | L260: =(K260)>(H260) -> FALSE | M260: 2 | N260: =(M260)>(K260) -> FALSE | O260: 0 | P260: =(O259)>(M259) -> FALSE | Q260: 0 | R260: =MOD(H260, 1) -> 0 | S260: =MOD(K260, 1) -> 0 | T260: =MOD(M260,1) -> 0 | U260: =MOD(O260,1) -> 0
...

Sheet Dashboard
A1: Marketing Campaign Performance - February 2021
A3: Ad spending | D3: Recorded revenue | G3: Orders | J3: ROAS
A4: =GETPIVOTDATA("Sum of mark_spent",'Campaign-summary'!$A$3) -> 30590880 | D4: =GETPIVOTDATA("Sum of revenue",'Campaign-summary'!$A$3) -> 42889366 | G4: =GETPIVOTDATA("Sum of orders",'Campaign-summary'!$A$3) -> 8043 | J4: ='Campaign-summary'!N15 -> 1.4020311
AA6: Campaign | AB6: ROAS
AA7: youtube_blogger | AB7: =_xlfn.XLOOKUP(AA7,'Campaign-summary'!$A$4:$A$14,'Campaign-summary'!$N$4:$N$14, "Not found") -> 3.7732066
AA8: facebook_retargeting | AB8: =_xlfn.XLOOKUP(AA8,'Campaign-summary'!$A$4:$A$14,'Campaign-summary'!$N$4:$N$14, "Not found") -> 2.0149608
AA9: google_hot | AB9: =_xlfn.XLOOKUP(AA9,'Campaign-summary'!$A$4:$A$14,'Campaign-summary'!$N$4:$N$14, "Not found") -> 1.8381244
AA10: instagram_tier1 | AB10: =_xlfn.XLOOKUP(AA10,'Campaign-summary'!$A$4:$A$14,'Campaign-summary'!$N$4:$N$14, "Not found") -> 1.7713968
AA11: instagram_blogger | AB11: =_xlfn.XLOOKUP(AA11,'Campaign-summary'!$A$4:$A$14,'Campaign-summary'!$N$4:$N$14, "Not found") -> 1.3675421
AA12: banner_partner | AB12: =_xlfn.XLOOKUP(AA12,'Campaign-summary'!$A$4:$A$14,'Campaign-summary'!$N$4:$N$14, "Not found") -> 1.2240617
AA13: facebook_tier1 | AB13: =_xlfn.XLOOKUP(AA13,'Campaign-summary'!$A$4:$A$14,'Campaign-summary'!$N$4:$N$14, "Not found") -> 0.93434891
AA14: facebook_tier2 | AB14: =_xlfn.XLOOKUP(AA14,'Campaign-summary'!$A$4:$A$14,'Campaign-summary'!$N$4:$N$14, "Not found") -> 0.73783579
AA15: google_wide | AB15: =_xlfn.XLOOKUP(AA15,'Campaign-summary'!$A$4:$A$14,'Campaign-summary'!$N$4:$N$14, "Not found") -> 0.66329726
AA16: instagram_tier2 | AB16: =_xlfn.XLOOKUP(AA16,'Campaign-summary'!$A$4:$A$14,'Campaign-summary'!$N$4:$N$14, "Not found") -> 0.62885864
AA17: facebook_lal | AB17: =_xlfn.XLOOKUP(AA17,'Campaign-summary'!$A$4:$A$14,'Campaign-summary'!$N$4:$N$14, "Not found") -> 0.11364114
AA22: Date | AB22: Daily ROAS | AC22: Monthly ROAS
AA23: 44228 | AB23: =_xlfn.XLOOKUP(AA23,Daily_analysis!$A$4:$A$31,Daily_analysis!$E$4:$E$31,"Not found") -> 1.5116589 | AC23: ='Campaign-summary'!$N$15 -> 1.4020311
AA24: 44229 | AB24: =_xlfn.XLOOKUP(AA24,Daily_analysis!$A$4:$A$31,Daily_analysis!$E$4:$E$31,"Not found") -> 1.6733354 | AC24: ='Campaign-summary'!$N$15 -> 1.4020311
AA25: 44230 | AB25: =_xlfn.XLOOKUP(AA25,Daily_analysis!$A$4:$A$31,Daily_analysis!$E$4:$E$31,"Not found") -> 1.7155703 | AC25: ='Campaign-summary'!$N$15 -> 1.4020311
AA26: 44231 | AB26: =_xlfn.XLOOKUP(AA26,Daily_analysis!$A$4:$A$31,Daily_analysis!$E$4:$E$31,"Not found") -> 1.3984822 | AC26: ='Campaign-summary'!$N$15 -> 1.4020311
AA27: 44232 | AB27: =_xlfn.XLOOKUP(AA27,Daily_analysis!$A$4:$A$31,Daily_analysis!$E$4:$E$31,"Not found") -> 1.4356357 | AC27: ='Campaign-summary'!$N$15 -> 1.4020311
AA28: 44233 | AB28: =_xlfn.XLOOKUP(AA28,Daily_analysis!$A$4:$A$31,Daily_analysis!$E$4:$E$31,"Not found") -> 1.3602019 | AC28: ='Campaign-summary'!$N$15 -> 1.4020311
AA29: 44234 | AB29: =_xlfn.XLOOKUP(AA29,Daily_analysis!$A$4:$A$31,Daily_analysis!$E$4:$E$31,"Not found") -> 1.4184789 | AC29: ='Campaign-summary'!$N$15 -> 1.4020311
AA30: 44235 | AB30: =_xlfn.XLOOKUP(AA30,Daily_analysis!$A$4:$A$31,Daily_analysis!$E$4:$E$31,"Not found") -> 1.3525431 | AC30: ='Campaign-summary'!$N$15 -> 1.4020311
AA31: 44236 | AB31: =_xlfn.XLOOKUP(AA31,Daily_analysis!$A$4:$A$31,Daily_analysis!$E$4:$E$31,"Not found") -> 1.3959194 | AC31: ='Campaign-summary'!$N$15 -> 1.4020311
AA32: 44237 | AB32: =_xlfn.XLOOKUP(AA32,Daily_analysis!$A$4:$A$31,Daily_analysis!$E$4:$E$31,"Not found") -> 1.1115296 | AC32: ='Campaign-summary'!$N$15 -> 1.4020311
AA33: 44238 | AB33: =_xlfn.XLOOKUP(AA33,Daily_analysis!$A$4:$A$31,Daily_analysis!$E$4:$E$31,"Not found") -> 1.7005342 | AC33: ='Campaign-summary'!$N$15 -> 1.4020311
AA34: 44239 | AB34: =_xlfn.XLOOKUP(AA34,Daily_analysis!$A$4:$A$31,Daily_analysis!$E$4:$E$31,"Not found") -> 1.4347744 | AC34: ='Campaign-summary'!$N$15 -> 1.4020311
... AA50: 44255 | AB50: =_xlfn.XLOOKUP(AA50,Daily_analysis!$A$4:$A$31,Daily_analysis!$E$4:$E$31,"Not found") -> 1.4272899 | AC50: ='Campaign-summary'!$N$15 -> 1.4020311
AA54: Category | AB54: February spending
AA55: social | AB55: =_xlfn.XLOOKUP(AA55,Category_analysis!$A$4:$A$7,Category_analysis!$B$4:$B$7,"Not found") -> 13798501
AA56: influencer | AB56: =_xlfn.XLOOKUP(AA56,Category_analysis!$A$4:$A$7,Category_analysis!$B$4:$B$7,"Not found") -> 8305304.1
AA57: media | AB57: =_xlfn.XLOOKUP(AA57,Category_analysis!$A$4:$A$7,Category_analysis!$B$4:$B$7,"Not found") -> 5026674.8
AA58: search | AB58: =_xlfn.XLOOKUP(AA58,Category_analysis!$A$4:$A$7,Category_analysis!$B$4:$B$7,"Not found") -> 3460400.1

Sheet buget_scenarios
A1: youtube_blogger | B1: Column1
A3: Assumed contribution margin before advertising | B3: 0.4
A4: Break-even ROAS | B4: =1/B3 -> 2.5
A5: Historical ROAS | B5: =youtube_blogger!D4 -> 3.7732066
A6: Meets assumed break-even threshold? | B6: =IF(B5>=B4,"True","False") -> True
A8: Hypothetical margin; excludes fixed overhead. Historical ROAS does not predict future returns.
A9: Minimum margin required at historical ROAS | B9: =1/B5 -> 0.26502657
A12: Campaign | B12: Historical ROAS | C12: Minimum required margin | D12: Note | E12: Meet threshold?
A13: youtube_blogger | B13: =_xlfn.XLOOKUP(A13,'Campaign-summary'!$A$4:$A$14, 'Campaign-summary'!$N$4:$N$14, "Not found") -> 3.7732066 | C13: =1/B13 -> 0.26502657 | E13: =B13>=$B$4 -> TRUE
A14: facebook_tier2 | B14: =_xlfn.XLOOKUP(A14,'Campaign-summary'!$A$4:$A$14, 'Campaign-summary'!$N$4:$N$14, "Not found") -> 0.73783579 | C14: =1/B14 -> 1.3553151 | D14: Exceeds 100%; recorded revenue cannot cover advertising, even before other costs. | E14: =B14>=$B$4 -> FALSE
A15: banner_partner | B15: =_xlfn.XLOOKUP(A15,'Campaign-summary'!$A$4:$A$14, 'Campaign-summary'!$N$4:$N$14, "Not found") -> 1.2240617 | C15: =1/B15 -> 0.81695229 | E15: =B15>=$B$4 -> FALSE
A16: facebook_lal | B16: =_xlfn.XLOOKUP(A16,'Campaign-summary'!$A$4:$A$14, 'Campaign-summary'!$N$4:$N$14, "Not found") -> 0.11364114 | C16: =1/B16 -> 8.7996298 | D16: Exceeds 100%; recorded revenue cannot cover advertising, even before other costs. | E16: =B16>=$B$4 -> FALSE
A17: facebook_retargeting | B17: =_xlfn.XLOOKUP(A17,'Campaign-summary'!$A$4:$A$14, 'Campaign-summary'!$N$4:$N$14, "Not found") -> 2.0149608 | C17: =1/B17 -> 0.49628756 | E17: =B17>=$B$4 -> FALSE
A18: facebook_tier1 | B18: =_xlfn.XLOOKUP(A18,'Campaign-summary'!$A$4:$A$14, 'Campaign-summary'!$N$4:$N$14, "Not found") -> 0.93434891 | C18: =1/B18 -> 1.070264 | D18: Exceeds 100%; recorded revenue cannot cover advertising, even before other costs. | E18: =B18>=$B$4 -> FALSE
A19: google_hot | B19: =_xlfn.XLOOKUP(A19,'Campaign-summary'!$A$4:$A$14, 'Campaign-summary'!$N$4:$N$14, "Not found") -> 1.8381244 | C19: =1/B19 -> 0.54403282 | E19: =B19>=$B$4 -> FALSE
A20: google_wide | B20: =_xlfn.XLOOKUP(A20,'Campaign-summary'!$A$4:$A$14, 'Campaign-summary'!$N$4:$N$14, "Not found") -> 0.66329726 | C20: =1/B20 -> 1.5076197 | D20: Exceeds 100%; recorded revenue cannot cover advertising, even before other costs. | E20: =B20>=$B$4 -> FALSE
A21: instagram_blogger | B21: =_xlfn.XLOOKUP(A21,'Campaign-summary'!$A$4:$A$14, 'Campaign-summary'!$N$4:$N$14, "Not found") -> 1.3675421 | C21: =1/B21 -> 0.73123891 | E21: =B21>=$B$4 -> FALSE
A22: instagram_tier1 | B22: =_xlfn.XLOOKUP(A22,'Campaign-summary'!$A$4:$A$14, 'Campaign-summary'!$N$4:$N$14, "Not found") -> 1.7713968 | C22: =1/B22 -> 0.56452624 | E22: =B22>=$B$4 -> FALSE
A23: instagram_tier2 | B23: =_xlfn.XLOOKUP(A23,'Campaign-summary'!$A$4:$A$14, 'Campaign-summary'!$N$4:$N$14, "Not found") -> 0.62885864 | C23: =1/B23 -> 1.5901825 | D23: Exceeds 100%; recorded revenue cannot cover advertising, even before other costs. | E23: =B23>=$B$4 -> FALSE
A26: Campaign | B26: Proposed action | C26: Supporting evidence | D26: What to verify
A27: facebook_lal | B27: Reduce budget, subject to verification | C27: ROAS 0.11; recorded revenue was 2.34 million below ad spending | D27: Spending and revenue attribution, delayed purchases, and campaign objective
A28: instagram_tier2 | B28: Cautiously reduce budget while investigating conversion | C28: ROAS 0.63; lead-to-order ratio 3.02%, versus social’s 8.40% | D28: Lead qualification and purchase-path drop-offs; linked purchase dates to check for delayed orders
A29: youtube_blogger | B29: Test a limited budget increase if economics and capacity support it | C29: Highest historical ROAS, 3.77; recorded revenue exceeded ad spending every day | D29: Actual contribution margin, costs included in mark_spent, placement availability, and returns during the test
A30: facebook_tier2 | B30: Cautiously reduce budget, subject to verification | C30: ROAS 0.74; recorded revenue below ad spending every day | D30: Tracking and delayed purchases; reasons for expensive clicks on Feb 15–16 and weak orders per lead on Feb 18
A31: facebook_retargeting | B31: Hold off on increasing budget; review current spending if margins are insufficient | C31: Historical ROAS of 2.01 requires a contribution margin before advertising of approximately 49.63% to break even before fixed costs | D31: Actual contribution margin, costs included in mark_spent, and whether additional spending can meet the required return
A32: instagram_tier1 | B32: Hold off on increasing budget; review current spending if margins are insufficient | C32: Historical ROAS of 1.77 requires a contribution margin before advertising of approximately 56.45% to break even before fixed costs | D32: Actual contribution margin, costs included in mark_spent, and whether additional spending could meet the required return
A33: facebook_tier1 | B33: Review for a cautious budget reduction | C33: ROAS 0.93; required margin 107.03%, exceeding 100% | D33: Tracking accuracy, delayed purchases, and campaign objective
A34: google_wide | B34: Review for a cautious budget reduction | C34: ROAS 0.66; required margin 150.76%, exceeding 100% | D34: Tracking accuracy, delayed purchases, and whether targeting attracts relevant traffic
A35: banner_partner | B35: Hold off on increases; review current spending if margins are insufficient | C35: ROAS 1.22; required margin 81.70% | D35: Actual margin and advertising costs; separately investigate unusual impressions affecting CTR and CPM
A36: google_hot | B36: Consider a limited increase test only if economics support it | C36: ROAS 1.84; required margin 54.40% | D36: Actual margin, performance consistency, and availability of additional relevant traffic
A37: instagram_blogger | B37: Hold off on increases pending margin verification | C37: ROAS 1.37; required margin 73.12% | D37: Actual margin, blogger fees included in spending, and terms for additional placements
A39: Budget Allocation Scenarios
A41: Campaign | B41: February spending | C41: Proposed change % | D41: Proposed spending | E41: Budget released/added | F41: Above February spending?
A42: banner_partner | B42: =_xlfn.XLOOKUP(A42,'Campaign-summary'!$A$4:$A$14,'Campaign-summary'!$B$4:$B$14,"Not found") -> 5026674.8 | C42: 0 | D42: =B42*(1+C42) -> 5026674.8 | E42: =B42-D42 -> 0 | F42: =E42<0 -> FALSE
A43: facebook_lal | B43: =_xlfn.XLOOKUP(A43,'Campaign-summary'!$A$4:$A$14,'Campaign-summary'!$B$4:$B$14,"Not found") -> 2641939.2 | C43: -0.1 | D43: =B43*(1+C43) -> 2377745.3 | E43: =B43-D43 -> 264193.92 | F43: =E43<0 -> FALSE
A44: facebook_retargeting | B44: =_xlfn.XLOOKUP(A44,'Campaign-summary'!$A$4:$A$14,'Campaign-summary'!$B$4:$B$14,"Not found") -> 266466.22 | C44: 0 | D44: =B44*(1+C44) -> 266466.22 | E44: =B44-D44 -> 0 | F44: =E44<0 -> FALSE
A45: facebook_tier1 | B45: =_xlfn.XLOOKUP(A45,'Campaign-summary'!$A$4:$A$14,'Campaign-summary'!$B$4:$B$14,"Not found") -> 2564793.5 | C45: 0 | D45: =B45*(1+C45) -> 2564793.5 | E45: =B45-D45 -> 0 | F45: =E45<0 -> FALSE
A46: facebook_tier2 | B46: =_xlfn.XLOOKUP(A46,'Campaign-summary'!$A$4:$A$14,'Campaign-summary'!$B$4:$B$14,"Not found") -> 4693871 | C46: 0 | D46: =B46*(1+C46) -> 4693871 | E46: =B46-D46 -> 0 | F46: =E46<0 -> FALSE
A47: google_hot | B47: =_xlfn.XLOOKUP(A47,'Campaign-summary'!$A$4:$A$14,'Campaign-summary'!$B$4:$B$14,"Not found") -> 1199998.8 | C47: 0 | D47: =B47*(1+C47) -> 1199998.8 | E47: =B47-D47 -> 0 | F47: =E47<0 -> FALSE
A48: google_wide | B48: =_xlfn.XLOOKUP(A48,'Campaign-summary'!$A$4:$A$14,'Campaign-summary'!$B$4:$B$14,"Not found") -> 2260401.3 | C48: 0 | D48: =B48*(1+C48) -> 2260401.3 | E48: =B48-D48 -> 0 | F48: =E48<0 -> FALSE
...

Sheet Campaign-summary
A1: category | B1: (All)
A3: Row Labels | B3: Sum of mark_spent | C3: Sum of orders | D3: Sum of revenue | E3: Sum of impressions | F3: Sum of clicks | G3: Sum of leads | H3: CTR | I3: CPC | J3: Click-to-lead conversion rate | K3: Lead-to-order conversion rate | L3: Click-to-order conversion rate | M3: Spending minus revenue | N3: ROAS | O3: Average order value | P3: Cost per order | Q3: Cost per lead | R3: CPM
A4: banner_partner | B4: 5026674.8 | C4: 1566 | D4: 6152960 | E4: 1068337427 | F4: 420003 | G4: 10149 | H4: =F4/E4 -> 0.00039313703 | I4: =B4/F4 -> 11.968188 | J4: =G4/F4 -> 0.024164113 | K4: =C4/G4 -> 0.15430092 | L4: =C4/F4 -> 0.0037285448 | M4: =B4-D4 -> -1126285.2 | N4: =(D4)/(B4) -> 1.2240617 | O4: =(D4)/(C4) -> 3929.0932 | P4: =(B4)/(C4) -> 3209.8817 | Q4: =B4/G4 -> 495.28769 | R4: =(B4/E4)*1000 -> 4.7051378
A5: facebook_lal | B5: 2641939.2 | C5: 294 | D5: 300233 | E5: 12697701 | F5: 120012 | G5: 1909 | H5: =F5/E5 -> 0.0094514747 | I5: =B5/F5 -> 22.013959 | J5: =G5/F5 -> 0.015906743 | K5: =C5/G5 -> 0.15400733 | L5: =C5/F5 -> 0.002449755 | M5: =B5-D5 -> 2341706.2 | N5: =(D5)/(B5) -> 0.11364114 | O5: =(D5)/(C5) -> 1021.2007 | P5: =(B5)/(C5) -> 8986.1879 | Q5: =B5/G5 -> 1383.9388 | R5: =(B5/E5)*1000 -> 208.06438
A6: facebook_retargeting | B6: 266466.22 | C6: 108 | D6: 536919 | E6: 976685 | F6: 29954 | G6: 506 | H6: =F6/E6 -> 0.030669049 | I6: =B6/F6 -> 8.8958476 | J6: =G6/F6 -> 0.016892569 | K6: =C6/G6 -> 0.21343874 | L6: =C6/F6 -> 0.0036055285 | M6: =B6-D6 -> -270452.78 | N6: =(D6)/(B6) -> 2.0149608 | O6: =(D6)/(C6) -> 4971.4722 | P6: =(B6)/(C6) -> 2467.2798 | Q6: =B6/G6 -> 526.61308 | R6: =(B6/E6)*1000 -> 272.82719
A7: facebook_tier1 | B7: 2564793.5 | C7: 474 | D7: 2396412 | E7: 63044882 | F7: 239997 | G7: 3535 | H7: =F7/E7 -> 0.0038067642 | I7: =B7/F7 -> 10.686773 | J7: =G7/F7 -> 0.014729351 | K7: =C7/G7 -> 0.13408769 | L7: =C7/F7 -> 0.0019750247 | M7: =B7-D7 -> 168381.48 | N7: =(D7)/(B7) -> 0.93434891 | O7: =(D7)/(C7) -> 5055.7215 | P7: =(B7)/(C7) -> 5410.9567 | Q7: =B7/G7 -> 725.54271 | R7: =(B7/E7)*1000 -> 40.682025
A8: facebook_tier2 | B8: 4693871 | C8: 688 | D8: 3463306 | E8: 69623161 | F8: 329973 | G8: 8428 | H8: =F8/E8 -> 0.0047394142 | I8: =B8/F8 -> 14.225015 | J8: =G8/F8 -> 0.025541484 | K8: =C8/G8 -> 0.081632653 | L8: =C8/F8 -> 0.0020850191 | M8: =B8-D8 -> 1230565 | N8: =(D8)/(B8) -> 0.73783579 | O8: =(D8)/(C8) -> 5033.875 | P8: =(B8)/(C8) -> 6822.4869 | Q8: =B8/G8 -> 556.9377 | R8: =(B8/E8)*1000 -> 67.41824
A9: google_hot | B9: 1199998.8 | C9: 281 | D9: 2205747 | E9: 4628993 | F9: 90048 | G9: 1833 | H9: =F9/E9 -> 0.019453043 | I9: =B9/F9 -> 13.326212 | J9: =G9/F9 -> 0.02035581 | K9: =C9/G9 -> 0.1533006 | L9: =C9/F9 -> 0.0031205579 | M9: =B9-D9 -> -1005748.2 | N9: =(D9)/(B9) -> 1.8381244 | O9: =(D9)/(C9) -> 7849.6335 | P9: =(B9)/(C9) -> 4270.4582 | Q9: =B9/G9 -> 654.66381 | R9: =(B9/E9)*1000 -> 259.23538
A10: google_wide | B10: 2260401.3 | C10: 547 | D10: 1499318 | E10: 67669259 | F10: 240006 | G10: 5274 | H10: =F10/E10 -> 0.0035467508 | I10: =B10/F10 -> 9.4181033 | J10: =G10/F10 -> 0.021974451 | K10: =C10/G10 -> 0.10371634 | L10: =C10/F10 -> 0.0022791097 | M10: =B10-D10 -> 761083.31 | N10: =(D10)/(B10) -> 0.66329726 | O10: =(D10)/(C10) -> 2740.9835 | P10: =(B10)/(C10) -> 4132.3607 | Q10: =B10/G10 -> 428.59335 | R10: =(B10/E10)*1000 -> 33.403666
A11: instagram_blogger | B11: 4247367.6 | C11: 1100 | D11: 5808454 | E11: 34112411 | F11: 299959 | G11: 7008 | H11: =F11/E11 -> 0.0087932512 | I11: =B11/F11 -> 14.159827 | J11: =G11/F11 -> 0.023363193 | K11: =C11/G11 -> 0.15696347 | L11: =C11/F11 -> 0.0036671678 | M11: =B11-D11 -> -1561086.4 | N11: =(D11)/(B11) -> 1.3675421 | O11: =(D11)/(C11) -> 5280.4127 | P11: =(B11)/(C11) -> 3861.2432 | Q11: =B11/G11 -> 606.07414 | R11: =(B11/E11)*1000 -> 124.51092
A12: instagram_tier1 | B12: 2565277.2 | C12: 758 | D12: 4544124 | E12: 75136799 | F12: 269961 | G12: 6632 | H12: =F12/E12 -> 0.0035929265 | I12: =B12/F12 -> 9.5023994 | J12: =G12/F12 -> 0.024566511 | K12: =C12/G12 -> 0.11429433 | L12: =C12/F12 -> 0.002807813 | M12: =B12-D12 -> -1978846.8 | N12: =(D12)/(B12) -> 1.7713968 | O12: =(D12)/(C12) -> 5994.8865 | P12: =(B12)/(C12) -> 3384.2708 | Q12: =B12/G12 -> 386.80296 | R12: =(B12/E12)*1000 -> 34.141423
A13: instagram_tier2 | B13: 1066153.8 | C13: 313 | D13: 670460 | E13: 137806768 | F13: 509992 | G13: 10374 | H13: =F13/E13 -> 0.0037007761 | I13: =B13/F13 -> 2.0905303 | J13: =G13/F13 -> 0.020341496 | K13: =C13/G13 -> 0.030171583 | L13: =C13/F13 -> 0.00061373512 | M13: =B13-D13 -> 395693.75 | N13: =(D13)/(B13) -> 0.62885864 | O13: =(D13)/(C13) -> 2142.0447 | P13: =(B13)/(C13) -> 3406.242 | Q13: =B13/G13 -> 102.77171 | R13: =(B13/E13)*1000 -> 7.7365848
A14: youtube_blogger | B14: 4057936.5 | C14: 1914 | D14: 15311433 | E14: 43688313 | F14: 450014 | G14: 9931 | H14: =F14/E14 -> 0.010300558 | I14: =B14/F14 -> 9.0173561 | J14: =G14/F14 -> 0.022068202 | K14: =C14/G14 -> 0.19272984 | L14: =C14/F14 -> 0.004253201 | M14: =B14-D14 -> -11253496 | N14: =(D14)/(B14) -> 3.7732066 | O14: =(D14)/(C14) -> 7999.7038 | P14: =(B14)/(C14) -> 2120.134 | Q14: =B14/G14 -> 408.61308 | R14: =(B14/E14)*1000 -> 92.8838
A15: Grand Total | B15: 30590880 | C15: 8043 | D15: 42889366 | E15: 1577722399 | F15: 2999919 | G15: 65579 | H15: =F15/E15 -> 0.0019014239 | I15: =B15/F15 -> 10.197235 | J15: =G15/F15 -> 0.021860257 | K15: =C15/G15 -> 0.12264597 | L15: =C15/F15 -> 0.0026810724 | M15: =B15-D15 -> -12298486 | N15: =(D15)/(B15) -> 1.4020311 | O15: =(D15)/(C15) -> 5332.5085 | P15: =(B15)/(C15) -> 3803.4166 | Q15: =B15/G15 -> 466.47372 | R15: =(B15/E15)*1000 -> 19.389266

Sheet Category_analysis
A3: Row Labels | B3: Sum of mark_spent | C3: Sum of orders | D3: Sum of revenue | E3: Sum of clicks | F3: Sum of leads | G3: Category ROAS | H3: Category cost per order | I3: Category AOV | J3: Category CPC | K3: Click-to-order rate | L3: Click-to-lead rate | M3: Lead-to-order rate
A4: influencer | B4: 8305304.1 | C4: 3014 | D4: 21119887 | E4: 749973 | F4: 16939 | G4: =D4/B4 -> 2.5429396 | H4: =B4/C4 -> 2755.5753 | I4: =D4/C4 -> 7007.2618 | J4: =B4/E4 -> 11.074137 | K4: =C4/E4 -> 0.0040188113 | L4: =F4/E4 -> 0.022586146 | M4: =C4/F4 -> 0.17793258
A5: media | B5: 5026674.8 | C5: 1566 | D5: 6152960 | E5: 420003 | F5: 10149 | G5: =D5/B5 -> 1.2240617 | H5: =B5/C5 -> 3209.8817 | I5: =D5/C5 -> 3929.0932 | J5: =B5/E5 -> 11.968188 | K5: =C5/E5 -> 0.0037285448 | L5: =F5/E5 -> 0.024164113 | M5: =C5/F5 -> 0.15430092
A6: search | B6: 3460400.1 | C6: 828 | D6: 3705065 | E6: 330054 | F6: 7107 | G6: =D6/B6 -> 1.0707042 | H6: =B6/C6 -> 4179.2271 | I6: =D6/C6 -> 4474.7162 | J6: =B6/E6 -> 10.484345 | K6: =C6/E6 -> 0.0025086804 | L6: =F6/E6 -> 0.02153284 | M6: =C6/F6 -> 0.11650485
A7: social | B7: 13798501 | C7: 2635 | D7: 11911454 | E7: 1499889 | F7: 31384 | G7: =D7/B7 -> 0.86324261 | H7: =B7/C7 -> 5236.6227 | I7: =D7/C7 -> 4520.4759 | J7: =B7/E7 -> 9.1996814 | K7: =C7/E7 -> 0.0017567967 | L7: =F7/E7 -> 0.020924215 | M7: =C7/F7 -> 0.08395998
A8: Grand Total | B8: 30590880 | C8: 8043 | D8: 42889366 | E8: 2999919 | F8: 65579 | G8: =D8/B8 -> 1.4020311 | H8: =B8/C8 -> 3803.4166 | I8: =D8/C8 -> 5332.5085 | J8: =B8/E8 -> 10.197235 | K8: =C8/E8 -> 0.0026810724 | L8: =F8/E8 -> 0.021860257 | M8: =C8/F8 -> 0.12264597

Sheet Daily_analysis
A3: Row Labels | B3: Sum of mark_spent | C3: Sum of orders | D3: Sum of revenue | E3: Daily ROAS | F3: Spending minus revenue | G3: Cost per order | H3: AOV | J3: Row Labels | K3: Sum of mark_spent | L3: Sum of orders | M3: Sum of revenue | N3: Category-date ROAS
A4: 44228 | B4: 120844.72 | C4: 30 | D4: 182676 | E4: 1.5116589 | F4: -61831.28 | G4: 4028.1573 | H4: 6089.2 | J4: 44237 | K4: 729951.8 | L4: 193 | M4: 811363 | N4: 1.1115296
A5: 44229 | B5: 189064.91 | C5: 54 | D5: 316369 | E5: 1.6733354 | F5: -127304.09 | G5: 3501.202 | H5: 5858.6852 | J5: influencer | K5: 146732.4 | L5: 50 | M5: 274656 | N5: 1.8718156
A6: 44230 | B6: 922808.01 | C6: 273 | D6: 1583142 | E6: 1.7155703 | F6: -660333.99 | G6: 3380.2491 | H6: 5799.0549 | J6: media | K6: 179519 | L6: 60 | M6: 196680 | N6: 1.0955943
A7: 44231 | B7: 1168337.4 | C7: 314 | D7: 1633899 | E7: 1.3984822 | F7: -465561.65 | G7: 3720.8196 | H7: 5203.5 | J7: search | K7: 119460.9 | L7: 30 | M7: 129322 | N7: 1.0825467
A8: 44232 | B8: 1883989.7 | C8: 475 | D8: 2704723 | E8: 1.4356357 | F8: -820733.26 | G8: 3966.2942 | H8: 5694.1537 | J8: social | K8: 284239.5 | L8: 53 | M8: 210705 | N8: 0.74129387
A9: 44233 | B9: 305983.26 | C9: 75 | D9: 416199 | E9: 1.3602019 | F9: -110215.74 | G9: 4079.7768 | H9: 5549.32 | J9: 44253 | K9: 122692.89 | L9: 38 | M9: 238748 | N9: 1.9458992
A10: 44234 | B10: 306417.68 | C10: 86 | D10: 434647 | E10: 1.4184789 | F10: -128229.32 | G10: 3562.9963 | H10: 5054.0349 | J10: influencer | K10: 54400.2 | L10: 21 | M10: 152901 | N10: 2.8106698
A11: 44235 | B11: 228203.45 | C11: 60 | D11: 308655 | E11: 1.3525431 | F11: -80451.55 | G11: 3803.3908 | H11: 5144.25 | J11: media | K11: 8087.73 | L11: 3 | M11: 12213 | N11: 1.5100652
A12: 44236 | B12: 313716.54 | C12: 82 | D12: 437923 | E12: 1.3959194 | F12: -124206.46 | G12: 3825.8115 | H12: 5340.5244 | J12: search | K12: 5998.84 | L12: 1 | M12: 2283 | N12: 0.38057358
A13: 44237 | B13: 729951.8 | C13: 193 | D13: 811363 | E13: 1.1115296 | F13: -81411.2 | G13: 3782.1337 | H13: 4203.9534 | J13: social | K13: 54206.12 | L13: 13 | M13: 71351 | N13: 1.3162905
A14: 44238 | B14: 919245.87 | C14: 260 | D14: 1563209 | E14: 1.7005342 | F14: -643963.13 | G14: 3535.561 | H14: 6012.3423 | J14: Grand Total | K14: 852644.69 | L14: 231 | M14: 1050111 | N14: 1.2315927
A15: 44239 | B15: 1155208.8 | C15: 314 | D15: 1657464 | E15: 1.4347744 | F15: -502255.2 | G15: 3679.0089 | H15: 5278.5478
A16: 44240 | B16: 1825406.9 | C16: 524 | D16: 2802893 | E16: 1.5354894 | F16: -977486.12 | G16: 3483.6009 | H16: 5349.0324
A17: 44241 | B17: 1881081.5 | C17: 466 | D17: 2197128 | E17: 1.1680132 | F17: -316046.46 | G17: 4036.6557 | H17: 4714.867 | J17: Date | K17: Influencer spending share
A18: 44242 | B18: 1941196.6 | C18: 516 | D18: 2795172 | E18: 1.4399222 | F18: -853975.44 | G18: 3762.0088 | H18: 5417 | J18: 44237 | K18: =K5/K4 -> 0.20101656
A19: 44243 | B19: 3035499 | C19: 692 | D19: 3620594 | E19: 1.1927508 | F19: -585095 | G19: 4386.5592 | H19: 5232.0723 | J19: 44253 | K19: =K10/K9 -> 0.44338511
A20: 44244 | B20: 3271291.5 | C20: 794 | D20: 4139131 | E20: 1.2652896 | F20: -867839.5 | G20: 4120.0145 | H20: 5213.0113
A21: 44245 | B21: 2158494.2 | C21: 520 | D21: 2659560 | E21: 1.2321367 | F21: -501065.8 | G21: 4150.9504 | H21: 5114.5385
A22: 44246 | B22: 3091011.3 | C22: 847 | D22: 4973240 | E22: 1.6089362 | F22: -1882228.7 | G22: 3649.364 | H22: 5871.5939
A23: 44247 | B23: 3499171.7 | C23: 1023 | D23: 5261521 | E23: 1.5036476 | F23: -1762349.3 | G23: 3420.5002 | H23: 5143.2268
A24: 44248 | B24: 301515.38 | C24: 86 | D24: 436892 | E24: 1.4489874 | F24: -135376.62 | G24: 3505.9928 | H24: 5080.1395
A25: 44249 | B25: 583694.38 | C25: 159 | D25: 893154 | E25: 1.5301741 | F25: -309459.62 | G25: 3671.0338 | H25: 5617.3208
A26: 44250 | B26: 117842.87 | C26: 33 | D26: 162649 | E26: 1.3802193 | F26: -44806.13 | G26: 3570.9961 | H26: 4928.7576
A27: 44251 | B27: 369238 | C27: 89 | D27: 440159 | E27: 1.1920739 | F27: -70921 | G27: 4148.7416 | H27: 4945.6067
A28: 44252 | B28: 66706.05 | C28: 20 | D28: 99303 | E28: 1.4886656 | F28: -32596.95 | G28: 3335.3025 | H28: 4965.15
A29: 44253 | B29: 122692.89 | C29: 38 | D29: 238748 | E29: 1.9458992 | F29: -116055.11 | G29: 3228.7603 | H29: 6282.8421
A30: 44254 | B30: 28902.73 | C30: 7 | D30: 42789 | E30: 1.4804484 | F30: -13886.27 | G30: 4128.9614 | H30: 6112.7143
A31: 44255 | B31: 53362.67 | C31: 13 | D31: 76164 | E31: 1.4272899 | F31: -22801.33 | G31: 4104.8208 | H31: 5858.7692
A32: Grand Total | B32: 30590880 | C32: 8043 | D32: 42889366 | E32: 1.4020311 | F32: -12298486 | G32: 3803.4166 | H32: 5332.5085

Sheet facebook_tier2
A3: Row Labels | B3: Sum of mark_spent | C3: Sum of revenue | D3: Sum of orders | E3: Sum of clicks | F3: Sum of leads | G3: Spend minus revenue | H3: ROAS | I3: Cost per order | J3: AOV | K3: CPC | L3: Click-to-order conversion rate | M3: Click-to-lead conversion rate | N3: Lead-to-order conversion rate
A4: facebook_tier2 | B4: 4693871 | C4: 3463306 | D4: 688 | E4: 329973 | F4: 8428 | G4: =(B4) - (C4) -> 1230565 | H4: =(C4)/(B4) -> 0.73783579 | I4: =IF(D4=0, "No orders", B4/D4) -> 6822.4869 | J4: =IF(D4=0,"No orders",C4/D4) -> 5033.875 | K4: =B4/E4 -> 14.225015 | L4: =D4/E4 -> 0.0020850191 | M4: =F4/E4 -> 0.025541484 | N4: =D4/F4 -> 0.081632653
A5: 44228 | B5: 16300.2 | C5: 14962 | D5: 3 | E5: 1640 | F5: 48 | G5: =(B5) - (C5) -> 1338.2 | H5: =(C5)/(B5) -> 0.91790285 | I5: =IF(D5=0, "No orders", B5/D5) -> 5433.4 | J5: =IF(D5=0,"No orders",C5/D5) -> 4987.3333 | K5: =B5/E5 -> 9.9391463 | L5: =D5/E5 -> 0.0018292683 | M5: =F5/E5 -> 0.029268293 | N5: =D5/F5 -> 0.0625
A6: 44229 | B6: 2198.05 | C6: 0 | D6: 0 | E6: 3294 | F6: 10 | G6: =(B6) - (C6) -> 2198.05 | H6: =(C6)/(B6) -> 0 | I6: =IF(D6=0, "No orders", B6/D6) -> No orders | J6: =IF(D6=0,"No orders",C6/D6) -> No orders | K6: =B6/E6 -> 0.66728901 | L6: =D6/E6 -> 0 | M6: =F6/E6 -> 0.0030358227 | N6: =D6/F6 -> 0
A7: 44230 | B7: 78958.3 | C7: 59772 | D7: 12 | E7: 9898 | F7: 226 | G7: =(B7) - (C7) -> 19186.3 | H7: =(C7)/(B7) -> 0.75700718 | I7: =IF(D7=0, "No orders", B7/D7) -> 6579.8583 | J7: =IF(D7=0,"No orders",C7/D7) -> 4981 | K7: =B7/E7 -> 7.9771974 | L7: =D7/E7 -> 0.0012123661 | M7: =F7/E7 -> 0.022832896 | N7: =D7/F7 -> 0.053097345
A8: 44231 | B8: 115389 | C8: 82909 | D8: 17 | E8: 13206 | F8: 143 | G8: =(B8) - (C8) -> 32480 | H8: =(C8)/(B8) -> 0.71851736 | I8: =IF(D8=0, "No orders", B8/D8) -> 6787.5882 | J8: =IF(D8=0,"No orders",C8/D8) -> 4877 | K8: =B8/E8 -> 8.7376193 | L8: =D8/E8 -> 0.0012872937 | M8: =F8/E8 -> 0.010828411 | N8: =D8/F8 -> 0.11888112
A9: 44232 | B9: 261047 | C9: 209202 | D9: 42 | E9: 16498 | F9: 330 | G9: =(B9) - (C9) -> 51845 | H9: =(C9)/(B9) -> 0.80139592 | I9: =IF(D9=0, "No orders", B9/D9) -> 6215.4048 | J9: =IF(D9=0,"No orders",C9/D9) -> 4981 | K9: =B9/E9 -> 15.822948 | L9: =D9/E9 -> 0.0025457631 | M9: =F9/E9 -> 0.020002425 | N9: =D9/F9 -> 0.12727273
A10: 44233 | B10: 62272.6 | C10: 44829 | D10: 9 | E10: 3302 | F10: 108 | G10: =(B10) - (C10) -> 17443.6 | H10: =(C10)/(B10) -> 0.71988322 | I10: =IF(D10=0, "No orders", B10/D10) -> 6919.1778 | J10: =IF(D10=0,"No orders",C10/D10) -> 4981 | K10: =B10/E10 -> 18.859055 | L10: =D10/E10 -> 0.0027256208 | M10: =F10/E10 -> 0.03270745 | N10: =D10/F10 -> 0.083333333
A11: 44234 | B11: 38485.6 | C11: 23735 | D11: 5 | E11: 3295 | F11: 66 | G11: =(B11) - (C11) -> 14750.6 | H11: =(C11)/(B11) -> 0.61672418 | I11: =IF(D11=0, "No orders", B11/D11) -> 7697.12 | J11: =IF(D11=0,"No orders",C11/D11) -> 4747 | K11: =B11/E11 -> 11.68 | L11: =D11/E11 -> 0.0015174507 | M11: =F11/E11 -> 0.020030349 | N11: =D11/F11 -> 0.075757576
A12: 44235 | B12: 33752.8 | C12: 28670 | D12: 5 | E12: 3290 | F12: 66 | G12: =(B12) - (C12) -> 5082.8 | H12: =(C12)/(B12) -> 0.84941101 | I12: =IF(D12=0, "No orders", B12/D12) -> 6750.56 | J12: =IF(D12=0,"No orders",C12/D12) -> 5734 | K12: =B12/E12 -> 10.25921 | L12: =D12/E12 -> 0.0015197568 | M12: =F12/E12 -> 0.02006079 | N12: =D12/F12 -> 0.075757576
A13: 44236 | B13: 62119.4 | C13: 54791 | D13: 11 | E13: 3303 | F13: 96 | G13: =(B13) - (C13) -> 7328.4 | H13: =(C13)/(B13) -> 0.88202719 | I13: =IF(D13=0, "No orders", B13/D13) -> 5647.2182 | J13: =IF(D13=0,"No orders",C13/D13) -> 4981 | K13: =B13/E13 -> 18.806963 | L13: =D13/E13 -> 0.0033303058 | M13: =F13/E13 -> 0.029064487 | N13: =D13/F13 -> 0.11458333
A14: 44237 | B14: 43865.9 | C14: 34867 | D14: 7 | E14: 6596 | F14: 132 | G14: =(B14) - (C14) -> 8998.9 | H14: =(C14)/(B14) -> 0.79485432 | I14: =IF(D14=0, "No orders", B14/D14) -> 6266.5571 | J14: =IF(D14=0,"No orders",C14/D14) -> 4981 | K14: =B14/E14 -> 6.650379 | L14: =D14/E14 -> 0.0010612492 | M14: =F14/E14 -> 0.020012129 | N14: =D14/F14 -> 0.053030303
A15: 44238 | B15: 188516 | C15: 131068 | D15: 28 | E15: 9895 | F15: 304 | G15: =(B15) - (C15) -> 57448 | H15: =(C15)/(B15) -> 0.69526194 | I15: =IF(D15=0, "No orders", B15/D15) -> 6732.7143 | J15: =IF(D15=0,"No orders",C15/D15) -> 4681 | K15: =B15/E15 -> 19.051642 | L15: =D15/E15 -> 0.002829712 | M15: =F15/E15 -> 0.030722587 | N15: =D15/F15 -> 0.092105263
A16: 44239 | B16: 191722 | C16: 176512 | D16: 32 | E16: 13196 | F16: 325 | G16: =(B16) - (C16) -> 15210 | H16: =(C16)/(B16) -> 0.92066638 | I16: =IF(D16=0, "No orders", B16/D16) -> 5991.3125 | J16: =IF(D16=0,"No orders",C16/D16) -> 5516 | K16: =B16/E16 -> 14.528797 | L16: =D16/E16 -> 0.0024249773 | M16: =F16/E16 -> 0.024628675 | N16: =D16/F16 -> 0.098461538
... A31: 44254 | B31: 3235.77 | C31: 0 | D31: 0 | E31: 332 | F31: 13 | G31: =(B31) - (C31) -> 3235.77 | H31: =(C31)/(B31) -> 0 | I31: =IF(D31=0, "No orders", B31/D31) -> No orders | J31: =IF(D31=0,"No orders",C31/D31) -> No orders | K31: =B31/E31 -> 9.7462952 | L31: =D31/E31 -> 0 | M31: =F31/E31 -> 0.039156627 | N31: =D31/F31 -> 0
A32: 44255 | B32: 8665.55 | C32: 5509 | D32: 1 | E32: 661 | F32: 13 | G32: =(B32) - (C32) -> 3156.55 | H32: =(C32)/(B32) -> 0.63573576 | I32: =(B32)/(D32) -> 8665.55 | J32: =IF(D32=0,"No orders",C32/D32) -> 5509 | K32: =B32/E32 -> 13.109758 | L32: =D32/E32 -> 0.0015128593 | M32: =F32/E32 -> 0.019667171 | N32: =D32/F32 -> 0.076923077
A33: Grand Total | B33: 4693871 | C33: 3463306 | D33: 688 | E33: 329973 | F33: 8428 | G33: =(B33) - (C33) -> 1230565 | H33: =(C33)/(B33) -> 0.73783579 | I33: =(B33)/(D33) -> 6822.4869 | J33: =IF(D33=0,"No orders",C33/D33) -> 5033.875 | K33: =B33/E33 -> 14.225015 | L33: =D33/E33 -> 0.0020850191 | M33: =F33/E33 -> 0.025541484 | N33: =D33/F33 -> 0.081632653

Sheet youtube_blogger
A3: Row Labels | B3: Sum of mark_spent | C3: Sum of revenue | D3: ROAS
A4: youtube_blogger | B4: 4057936.5 | C4: 15311433 | D4: =C4/B4 -> 3.7732066
A5: 44228 | B5: 29962.2 | C5: 84490 | D5: =C5/B5 -> 2.8198864
A6: 44229 | B6: 42301.1 | C6: 149141 | D6: =C6/B6 -> 3.5257003
A7: 44230 | B7: 189341 | C7: 772499 | D7: =C7/B7 -> 4.0799351
A8: 44231 | B8: 185263 | C8: 624958 | D8: =C8/B8 -> 3.3733557
A9: 44232 | B9: 442617 | C9: 1165230 | D9: =C9/B9 -> 2.6325921
A10: 44233 | B10: 80971.4 | C10: 215487 | D10: =C10/B10 -> 2.661273
A11: 44234 | B11: 31680.1 | C11: 119715 | D11: =C11/B11 -> 3.7788706
A12: 44235 | B12: 33892.6 | C12: 120176 | D12: =C12/B12 -> 3.5457888
A13: 44236 | B13: 27833 | C13: 143658 | D13: =C13/B13 -> 5.1614271
A14: 44237 | B14: 19831.4 | C14: 130768 | D14: =C14/B14 -> 6.5939873
A15: 44238 | B15: 197161 | C15: 831820 | D15: =C15/B15 -> 4.2189885
A16: 44239 | B16: 121652 | C16: 486841 | D16: =C16/B16 -> 4.0019153
... A32: 44255 | B32: 9892.77 | C32: 37450 | D32: =C32/B32 -> 3.7855929
A33: Grand Total | B33: 4057936.5 | C33: 15311433 | D33: =C33/B33 -> 3.7732066

Sheet instagram_tier2
A3: Row Labels | B3: Sum of leads | C3: Sum of orders | D3: Lead-to-order rate | E3: Orders at monthly benchmark | F3: Order gap vs monthly benchmark
A4: instagram_tier2 | B4: 10374 | C4: 313 | D4: =C4/B4 -> 0.030171583 | E4: =B4*3.02% -> 313.2948 | F4: =E4-C4 -> 0.2948
A5: 44247 | B5: 1224 | C5: 48 | D5: =C5/B5 -> 0.039215686 | E5: =B5*3.02% -> 36.9648 | F5: =E5-C5 -> -11.0352
A6: 44245 | B6: 1020 | C6: 16 | D6: =C6/B6 -> 0.015686275 | E6: =B6*3.02% -> 30.804 | F6: =E6-C6 -> 14.804
A7: 44244 | B7: 974 | C7: 46 | D7: =C7/B7 -> 0.047227926 | E7: =B7*3.02% -> 29.4148 | F7: =E7-C7 -> -16.5852
A8: 44241 | B8: 935 | C8: 54 | D8: =C8/B8 -> 0.057754011 | E8: =B8*3.02% -> 28.237 | F8: =E8-C8 -> -25.763
A9: 44242 | B9: 916 | C9: 11 | D9: =C9/B9 -> 0.012008734 | E9: =B9*3.02% -> 27.6632 | F9: =E9-C9 -> 16.6632
A10: 44243 | B10: 816 | C10: 24 | D10: =C10/B10 -> 0.029411765 | E10: =B10*3.02% -> 24.6432 | F10: =E10-C10 -> 0.6432
A11: 44232 | B11: 765 | C11: 4 | D11: =C11/B11 -> 0.0052287582 | E11: =B11*3.02% -> 23.103 | F11: =E11-C11 -> 19.103
A12: 44230 | B12: 592 | C12: 36 | D12: =C12/B12 -> 0.060810811 | E12: =B12*3.02% -> 17.8784 | F12: =E12-C12 -> -18.1216
A13: 44240 | B13: 510 | C13: 6 | D13: =C13/B13 -> 0.011764706 | E13: =B13*3.02% -> 15.402 | F13: =E13-C13 -> 9.402
A14: 44231 | B14: 408 | C14: 12 | D14: =C14/B14 -> 0.029411765 | E14: =B14*3.02% -> 12.3216 | F14: =E14-C14 -> 0.3216
A15: 44239 | B15: 408 | C15: 15 | D15: =C15/B15 -> 0.036764706 | E15: =B15*3.02% -> 12.3216 | F15: =E15-C15 -> -2.6784
A16: 44237 | B16: 395 | C16: 4 | D16: =C16/B16 -> 0.010126582 | E16: =B16*3.02% -> 11.929 | F16: =E16-C16 -> 7.929
... A32: 44254 | B32: 3 | C32: 0 | D32: =C32/B32 -> 0 | E32: =B32*3.02% -> 0.0906 | F32: =E32-C32 -> 0.0906
A33: Grand Total | B33: 10374 | C33: 313
